Workbook

Sheet 统计分析
B2: 概况 | C2: 成绩 | D2: =SUM('1号洞'!C81,'2号洞'!C81,'3号洞'!C81,'4号洞'!C81,'5号洞'!C81,'6号洞'!C81,'7号洞'!C81,'8号洞'!C81,'9号洞'!C81,'10号洞'!C81,'11号洞'!C81,'12号洞'!C81,'13号洞'!C81,'14号洞'!C81,'15号洞'!C81,'16号洞'!C81,'17号洞'!C81,'18号洞'!C81) -> 81 | F2: 开球 | G2: 开球球道 | H2: {=IFERROR(SUM('1号洞'!E90+0,'2号洞'!E90+0,'3号洞'!E90+0,'4号洞'!E90+0,'5号洞'!E90+0,'6号洞'!E90+0,'7号洞'!E90+0,'8号洞'!E90+0,'9号洞'!E90+0,'10号洞'!E90+0,'11号洞'!E90+0,'12号洞'!E90+0,'13号洞'!E90+0,'14号洞'!E90+0,'15号洞'!E90+0,'16号洞'!E90+0,'17号洞'!E90+0,'18号洞'!E90+0)/SUM('1号洞'!F90,'2号洞'!F90,'3号洞'!F90,'4号洞'!F90,'5号洞'!F90,'6号洞'!F90,'7号洞'!F90,'8号洞'!F90,'9号洞'!F90,'10号洞'!F90,'11号洞'!F90,'12号洞'!F90,'13号洞'!F90,'14号洞'!F90,'15号洞'!F90,'16号洞'!F90,'17号洞'!F90,'18号洞'!F90),“-”)} -> 0.92857143 | J2: 铁杆 | K2: 50-75上果岭率 | L2: {=IFERROR(SUM('1号洞'!D125,'2号洞'!D125,'3号洞'!D125,'4号洞'!D125,'5号洞'!D125,'6号洞'!D125,'7号洞'!D125,'8号洞'!D125,'9号洞'!D125,'10号洞'!D125,'11号洞'!D125,'12号洞'!D125,'13号洞'!D125,'14号洞'!D125,'15号洞'!D125,'16号洞'!D125,'17号洞'!D125,'18号洞'!D125)/SUM('1号洞'!C125,'2号洞'!C125,'3号洞'!C125,'4号洞'!C125,'5号洞'!C125,'6号洞'!C125,'7号洞'!C125,'8号洞'!C125,'9号洞'!C125,'10号洞'!C125,'11号洞'!C125,'12号洞'!C125,'13号洞'!C125,'14号洞'!C125,'15号洞'!C125,'16号洞'!C125,'17号洞'!C125,'18号洞'!C125),“-”)} -> 0.5 | O2: 切杆 | P2: 0-10yd救球成功率 | Q2: =IFERROR(SUM('1号洞'!E118,'2号洞'!E118,'3号洞'!E118,'4号洞'!E118,'5号洞'!E118,'6号洞'!E118,'7号洞'!E118,'8号洞'!E118,'9号洞'!E118,'10号洞'!E118,'11号洞'!E118,'12号洞'!E118,'13号洞'!E118,'14号洞'!E118,'15号洞'!E118,'16号洞'!E118,'17号洞'!E118,'18号洞'!E118)/SUM('1号洞'!D118,'2号洞'!D118,'3号洞'!D118,'4号洞'!D118,'5号洞'!D118,'6号洞'!D118,'7号洞'!D118,'8号洞'!D118,'9号洞'!D118,'10号洞'!D118,'11号洞'!D118,'12号洞'!D118,'13号洞'!D118,'14号洞'!D118,'15号洞'!D118,'16号洞'!D118,'17号洞'!D118,'18号洞'!D118),"-") -> 1 | T2: 推杆 | U2: 一推率 | V2: =SUM('1号洞'!F86,'2号洞'!F86,'3号洞'!F86,'4号洞'!F86,'5号洞'!F86,'6号洞'!F86,'7号洞'!F86,'8号洞'!F86,'9号洞'!F86,'10号洞'!F86,'11号洞'!F86,'12号洞'!F86,'13号洞'!F86,'14号洞'!F86,'15号洞'!F86,'16号洞'!F86,'17号洞'!F86,'18号洞'!F86)/18 -> 0.22222222
C3: 推杆 | D3: =SUM('1号洞'!C86,'2号洞'!C86,'3号洞'!C86,'4号洞'!C86,'5号洞'!C86,'6号洞'!C86,'7号洞'!C86,'8号洞'!C86,'9号洞'!C86,'10号洞'!C86,'11号洞'!C86,'12号洞'!C86,'13号洞'!C86,'14号洞'!C86,'15号洞'!C86,'16号洞'!C86,'17号洞'!C86,'18号洞'!C86) -> 33 | G3: 开球长草 | H3: {=IFERROR(SUM('1号洞'!H90,'2号洞'!H90,'3号洞'!H90,'4号洞'!H90,'5号洞'!H90,'6号洞'!H90,'7号洞'!H90,'8号洞'!H90,'9号洞'!H90,'10号洞'!H90,'11号洞'!H90,'12号洞'!H90,'13号洞'!H90,'14号洞'!H90,'15号洞'!H90,'16号洞'!H90,'17号洞'!H90,'18号洞'!H90)/SUM('1号洞'!F90,'2号洞'!F90,'3号洞'!F90,'4号洞'!F90,'5号洞'!F90,'6号洞'!F90,'7号洞'!F90,'8号洞'!F90,'9号洞'!F90,'10号洞'!F90,'11号洞'!F90,'12号洞'!F90,'13号洞'!F90,'14号洞'!F90,'15号洞'!F90,'16号洞'!F90,'17号洞'!F90,'18号洞'!F90),“-”)} -> 0 | K3: 75-100上果岭率 | L3: {=IFERROR(SUM('1号洞'!D126,'2号洞'!D126,'3号洞'!D126,'4号洞'!D126,'5号洞'!D126,'6号洞'!D126,'7号洞'!D126,'8号洞'!D126,'9号洞'!D126,'10号洞'!D126,'11号洞'!D126,'12号洞'!D126,'13号洞'!D126,'14号洞'!D126,'15号洞'!D126,'16号洞'!D126,'17号洞'!D126,'18号洞'!D126)/SUM('1号洞'!C126,'2号洞'!C126,'3号洞'!C126,'4号洞'!C126,'5号洞'!C126,'6号洞'!C126,'7号洞'!C126,'8号洞'!C126,'9号洞'!C126,'10号洞'!C126,'11号洞'!C126,'12号洞'!C126,'13号洞'!C126,'14号洞'!C126,'15号洞'!C126,'16号洞'!C126,'17号洞'!C126,'18号洞'!C126),“-”)} -> 1 | P3: 10-20yd救球成功率 | Q3: =IFERROR(SUM('1号洞'!E119,'2号洞'!E119,'3号洞'!E119,'4号洞'!E119,'5号洞'!E119,'6号洞'!E119,'7号洞'!E119,'8号洞'!E119,'9号洞'!E119,'10号洞'!E119,'11号洞'!E119,'12号洞'!E119,'13号洞'!E119,'14号洞'!E119,'15号洞'!E119,'16号洞'!E119,'17号洞'!E119,'18号洞'!E119)/SUM('1号洞'!D119,'2号洞'!D119,'3号洞'!D119,'4号洞'!D119,'5号洞'!D119,'6号洞'!D119,'7号洞'!D119,'8号洞'!D119,'9号洞'!D119,'10号洞'!D119,'11号洞'!D119,'12号洞'!D119,'13号洞'!D119,'14号洞'!D119,'15号洞'!D119,'16号洞'!D119,'17号洞'!D119,'18号洞'!D119),"-") -> 0 | U3: 三推数 | V3: =SUM('1号洞'!H86,'2号洞'!H86,'3号洞'!H86,'4号洞'!H86,'5号洞'!H86,'6号洞'!H86,'7号洞'!H86,'8号洞'!H86,'9号洞'!H86,'10号洞'!H86,'11号洞'!H86,'12号洞'!H86,'13号洞'!H86,'14号洞'!H86,'15号洞'!H86,'16号洞'!H86,'17号洞'!H86,'18号洞'!H86) -> 1
C4: 罚杆 | D4: =SUM('1号洞'!C83,'2号洞'!C83,'3号洞'!C83,'4号洞'!C83,'5号洞'!C83,'6号洞'!C83,'7号洞'!C83,'8号洞'!C83,'9号洞'!C83,'10号洞'!C83,'11号洞'!C83,'12号洞'!C83,'13号洞'!C83,'14号洞'!C83,'15号洞'!C83,'16号洞'!C83,'17号洞'!C83,'18号洞'!C83) -> 0 | G4: 开球沙坑 | H4: {=IFERROR(SUM('1号洞'!I90,'2号洞'!I90,'3号洞'!I90,'4号洞'!I90,'5号洞'!I90,'6号洞'!I90,'7号洞'!I90,'8号洞'!I90,'9号洞'!I90,'10号洞'!I90,'11号洞'!I90,'12号洞'!I90,'13号洞'!I90,'14号洞'!I90,'15号洞'!I90,'16号洞'!I90,'17号洞'!I90,'18号洞'!I90)/SUM('1号洞'!F90,'2号洞'!F90,'3号洞'!F90,'4号洞'!F90,'5号洞'!F90,'6号洞'!F90,'7号洞'!F90,'8号洞'!F90,'9号洞'!F90,'10号洞'!F90,'11号洞'!F90,'12号洞'!F90,'13号洞'!F90,'14号洞'!F90,'15号洞'!F90,'16号洞'!F90,'17号洞'!F90,'18号洞'!F90),“-”)} -> 0.071428571 | K4: 100-125上果岭率 | L4: {=IFERROR(SUM('1号洞'!D127,'2号洞'!D127,'3号洞'!D127,'4号洞'!D127,'5号洞'!D127,'6号洞'!D127,'7号洞'!D127,'8号洞'!D127,'9号洞'!D127,'10号洞'!D127,'11号洞'!D127,'12号洞'!D127,'13号洞'!D127,'14号洞'!D127,'15号洞'!D127,'16号洞'!D127,'17号洞'!D127,'18号洞'!D127)/SUM('1号洞'!C127,'2号洞'!C127,'3号洞'!C127,'4号洞'!C127,'5号洞'!C127,'6号洞'!C127,'7号洞'!C127,'8号洞'!C127,'9号洞'!C127,'10号洞'!C127,'11号洞'!C127,'12号洞'!C127,'13号洞'!C127,'14号洞'!C127,'15号洞'!C127,'16号洞'!C127,'17号洞'!C127,'18号洞'!C127),“-”)} -> 0.2 | P4: 20-30yd救球成功率 | Q4: =IFERROR(SUM('1号洞'!E120,'2号洞'!E120,'3号洞'!E120,'4号洞'!E120,'5号洞'!E120,'6号洞'!E120,'7号洞'!E120,'8号洞'!E120,'9号洞'!E120,'10号洞'!E120,'11号洞'!E120,'12号洞'!E120,'13号洞'!E120,'14号洞'!E120,'15号洞'!E120,'16号洞'!E120,'17号洞'!E120,'18号洞'!E120)/SUM('1号洞'!D120,'2号洞'!D120,'3号洞'!D120,'4号洞'!D120,'5号洞'!D120,'6号洞'!D120,'7号洞'!D120,'8号洞'!D120,'9号洞'!D120,'10号洞'!D120,'11号洞'!D120,'12号洞'!D120,'13号洞'!D120,'14号洞'!D120,'15号洞'!D120,'16号洞'!D120,'17号洞'!D120,'18号洞'!D120),"-") -> 0 | U4: 0-3推进概率 | V4: =IFERROR(SUM('1号洞'!D93,'2号洞'!D93,'3号洞'!D93,'4号洞'!D93,'5号洞'!D93,'6号洞'!D93,'7号洞'!D93,'8号洞'!D93,'9号洞'!D93,'10号洞'!D93,'11号洞'!D93,'12号洞'!D93,'13号洞'!D93,'14号洞'!D93,'15号洞'!D93,'16号洞'!D93,'17号洞'!D93,'18号洞'!D93)/SUM('1号洞'!C93,'2号洞'!C93,'3号洞'!C93,'4号洞'!C93,'5号洞'!C93,'6号洞'!C93,'7号洞'!C93,'8号洞'!C93,'9号洞'!C93,'10号洞'!C93,'11号洞'!C93,'12号洞'!C93,'13号洞'!C93,'14号洞'!C93,'15号洞'!C93,'16号洞'!C93,'17号洞'!C93,'18号洞'!C93),"-") -> 1
C5: 标杆上果岭率 | D5: =SUM('1号洞'!C87+0,'2号洞'!C87+0,'3号洞'!C87+0,'4号洞'!C87+0,'5号洞'!C87+0,'6号洞'!C87+0,'7号洞'!C87+0,'8号洞'!C87+0,'9号洞'!C87+0,'10号洞'!C87+0,'11号洞'!C87+0,'12号洞'!C87+0,'13号洞'!C87+0,'14号洞'!C87+0,'15号洞'!C87+0,'16号洞'!C87+0,'17号洞'!C87+0,'18号洞'!C87+0)/18 -> 0.33333333 | G5: 开球直球 | H5: {=IFERROR(SUM('1号洞'!J90,'2号洞'!J90,'3号洞'!J90,'4号洞'!J90,'5号洞'!J90,'6号洞'!J90,'7号洞'!J90,'8号洞'!J90,'9号洞'!J90,'10号洞'!J90,'11号洞'!J90,'12号洞'!J90,'13号洞'!J90,'14号洞'!J90,'15号洞'!J90,'16号洞'!J90,'17号洞'!J90,'18号洞'!J90)/SUM('1号洞'!F90,'2号洞'!F90,'3号洞'!F90,'4号洞'!F90,'5号洞'!F90,'6号洞'!F90,'7号洞'!F90,'8号洞'!F90,'9号洞'!F90,'10号洞'!F90,'11号洞'!F90,'12号洞'!F90,'13号洞'!F90,'14号洞'!F90,'15号洞'!F90,'16号洞'!F90,'17号洞'!F90,'18号洞'!F90),“-”)} -> 0.71428571 | K5: 125-150上果岭率 | L5: {=IFERROR(SUM('1号洞'!D128,'2号洞'!D128,'3号洞'!D128,'4号洞'!D128,'5号洞'!D128,'6号洞'!D128,'7号洞'!D128,'8号洞'!D128,'9号洞'!D128,'10号洞'!D128,'11号洞'!D128,'12号洞'!D128,'13号洞'!D128,'14号洞'!D128,'15号洞'!D128,'16号洞'!D128,'17号洞'!D128,'18号洞'!D128)/SUM('1号洞'!C128,'2号洞'!C128,'3号洞'!C128,'4号洞'!C128,'5号洞'!C128,'6号洞'!C128,'7号洞'!C128,'8号洞'!C128,'9号洞'!C128,'10号洞'!C128,'11号洞'!C128,'12号洞'!C128,'13号洞'!C128,'14号洞'!C128,'15号洞'!C128,'16号洞'!C128,'17号洞'!C128,'18号洞'!C128),“-”)} -> 0.5 | P5: 30-40yd救球成功率 | Q5: =IFERROR(SUM('1号洞'!E121,'2号洞'!E121,'3号洞'!E121,'4号洞'!E121,'5号洞'!E121,'6号洞'!E121,'7号洞'!E121,'8号洞'!E121,'9号洞'!E121,'10号洞'!E121,'11号洞'!E121,'12号洞'!E121,'13号洞'!E121,'14号洞'!E121,'15号洞'!E121,'16号洞'!E121,'17号洞'!E121,'18号洞'!E121)/SUM('1号洞'!D121,'2号洞'!D121,'3号洞'!D121,'4号洞'!D121,'5号洞'!D121,'6号洞'!D121,'7号洞'!D121,'8号洞'!D121,'9号洞'!D121,'10号洞'!D121,'11号洞'!D121,'12号洞'!D121,'13号洞'!D121,'14号洞'!D121,'15号洞'!D121,'16号洞'!D121,'17号洞'!D121,'18号洞'!D121),"-") -> 0 | U5: 3-9推进概率 | V5: =IFERROR(SUM('1号洞'!D94,'2号洞'!D94,'3号洞'!D94,'4号洞'!D94,'5号洞'!D94,'6号洞'!D94,'7号洞'!D94,'8号洞'!D94,'9号洞'!D94,'10号洞'!D94,'11号洞'!D94,'12号洞'!D94,'13号洞'!D94,'14号洞'!D94,'15号洞'!D94,'16号洞'!D94,'17号洞'!D94,'18号洞'!D94)/SUM('1号洞'!C94,'2号洞'!C94,'3号洞'!C94,'4号洞'!C94,'5号洞'!C94,'6号洞'!C94,'7号洞'!C94,'8号洞'!C94,'9号洞'!C94,'10号洞'!C94,'11号洞'!C94,'12号洞'!C94,'13号洞'!C94,'14号洞'!C94,'15号洞'!C94,'16号洞'!C94,'17号洞'!C94,'18号洞'!C94),"-") -> 0.88888889
C6: 一切一推率 | D6: =SUM('1号洞'!C75+0,'2号洞'!C75+0,'3号洞'!C75+0,'4号洞'!C75+0,'5号洞'!C75+0,'6号洞'!C75+0,'7号洞'!C75+0,'8号洞'!C75+0,'9号洞'!C75+0,'10号洞'!C75+0,'11号洞'!C75+0,'12号洞'!C75+0,'13号洞'!C75+0,'14号洞'!C75+0,'15号洞'!C75+0,'16号洞'!C75+0,'17号洞'!C75+0,'18号洞'!C88+0)/18 -> 0 | G6: 开球偏左 | H6: {=IFERROR(SUM('1号洞'!K90,'2号洞'!K90,'3号洞'!K90,'4号洞'!K90,'5号洞'!K90,'6号洞'!K90,'7号洞'!K90,'8号洞'!K90,'9号洞'!K90,'10号洞'!K90,'11号洞'!K90,'12号洞'!K90,'13号洞'!K90,'14号洞'!K90,'15号洞'!K90,'16号洞'!K90,'17号洞'!K90,'18号洞'!K90)/SUM('1号洞'!F90,'2号洞'!F90,'3号洞'!F90,'4号洞'!F90,'5号洞'!F90,'6号洞'!F90,'7号洞'!F90,'8号洞'!F90,'9号洞'!F90,'10号洞'!F90,'11号洞'!F90,'12号洞'!F90,'13号洞'!F90,'14号洞'!F90,'15号洞'!F90,'16号洞'!F90,'17号洞'!F90,'18号洞'!F90),“-”)} -> 0 | K6: 150-200上果岭率 | L6: {=IFERROR(SUM('1号洞'!D129,'2号洞'!D129,'3号洞'!D129,'4号洞'!D129,'5号洞'!D129,'6号洞'!D129,'7号洞'!D129,'8号洞'!D129,'9号洞'!D129,'10号洞'!D129,'11号洞'!D129,'12号洞'!D129,'13号洞'!D129,'14号洞'!D129,'15号洞'!D129,'16号洞'!D129,'17号洞'!D129,'18号洞'!D129)/SUM('1号洞'!C129,'2号洞'!C129,'3号洞'!C129,'4号洞'!C129,'5号洞'!C129,'6号洞'!C129,'7号洞'!C129,'8号洞'!C129,'9号洞'!C129,'10号洞'!C129,'11号洞'!C129,'12号洞'!C129,'13号洞'!C129,'14号洞'!C129,'15号洞'!C129,'16号洞'!C129,'17号洞'!C129,'18号洞'!C129),“-”)} -> 0 | P6: 40-50yd救球成功率 | Q6: =IFERROR(SUM('1号洞'!E122,'2号洞'!E122,'3号洞'!E122,'4号洞'!E122,'5号洞'!E122,'6号洞'!E122,'7号洞'!E122,'8号洞'!E122,'9号洞'!E122,'10号洞'!E122,'11号洞'!E122,'12号洞'!E122,'13号洞'!E122,'14号洞'!E122,'15号洞'!E122,'16号洞'!E122,'17号洞'!E122,'18号洞'!E122)/SUM('1号洞'!D122,'2号洞'!D122,'3号洞'!D122,'4号洞'!D122,'5号洞'!D122,'6号洞'!D122,'7号洞'!D122,'8号洞'!D122,'9号洞'!D122,'10号洞'!D122,'11号洞'!D122,'12号洞'!D122,'13号洞'!D122,'14号洞'!D122,'15号洞'!D122,'16号洞'!D122,'17号洞'!D122,'18号洞'!D122),"-") -> 0 | U6: 9-15推进概率 | V6: =IFERROR(SUM('1号洞'!D95,'2号洞'!D95,'3号洞'!D95,'4号洞'!D95,'5号洞'!D95,'6号洞'!D95,'7号洞'!D95,'8号洞'!D95,'9号洞'!D95,'10号洞'!D95,'11号洞'!D95,'12号洞'!D95,'13号洞'!D95,'14号洞'!D95,'15号洞'!D95,'16号洞'!D95,'17号洞'!D95,'18号洞'!D95)/SUM('1号洞'!C95,'2号洞'!C95,'3号洞'!C95,'4号洞'!C95,'5号洞'!C95,'6号洞'!C95,'7号洞'!C95,'8号洞'!C95,'9号洞'!C95,'10号洞'!C95,'11号洞'!C95,'12号洞'!C95,'13号洞'!C95,'14号洞'!C95,'15号洞'!C95,'16号洞'!C95,'17号洞'!C95,'18号洞'!C95),"-") -> 0.125
C7: 标上平均推杆 | D7: {=IFERROR(SUM('1号洞'!F87,'2号洞'!F87,'3号洞'!F87,'4号洞'!F87,'5号洞'!F87,'6号洞'!F87,'7号洞'!F87,'8号洞'!F87,'9号洞'!F87,'10号洞'!F87,'11号洞'!F87,'12号洞'!F87,'13号洞'!F87,'14号洞'!F87,'15号洞'!F87,'16号洞'!F87,'17号洞'!F87,'18号洞'!F87)/SUM('1号洞'!C87+0,'2号洞'!C87+0,'3号洞'!C87+0,'4号洞'!C87+0,'5号洞'!C87+0,'6号洞'!C87+0,'7号洞'!C87+0,'8号洞'!C87+0,'9号洞'!C87+0,'10号洞'!C87+0,'11号洞'!C87+0,'12号洞'!C87+0,'13号洞'!C87+0,'14号洞'!C87+0,'15号洞'!C87+0,'16号洞'!C87+0,'17号洞'!C87+0,'18号洞'!C87+0),“-”)} -> 1.8333333 | G7: 开球偏右 | H7: {=IFERROR(SUM('1号洞'!L90,'2号洞'!L90,'3号洞'!L90,'4号洞'!L90,'5号洞'!L90,'6号洞'!L90,'7号洞'!L90,'8号洞'!L90,'9号洞'!L90,'10号洞'!L90,'11号洞'!L90,'12号洞'!L90,'13号洞'!L90,'14号洞'!L90,'15号洞'!L90,'16号洞'!L90,'17号洞'!L90,'18号洞'!L90)/SUM('1号洞'!F90,'2号洞'!F90,'3号洞'!F90,'4号洞'!F90,'5号洞'!F90,'6号洞'!F90,'7号洞'!F90,'8号洞'!F90,'9号洞'!F90,'10号洞'!F90,'11号洞'!F90,'12号洞'!F90,'13号洞'!F90,'14号洞'!F90,'15号洞'!F90,'16号洞'!F90,'17号洞'!F90,'18号洞'!F90),“-”)} -> 0.28571429 | K7: 200以上上果岭率 | L7: =IFERROR(SUM('1号洞'!D130,'2号洞'!D130,'3号洞'!D130,'4号洞'!D130,'5号洞'!D130,'6号洞'!D130,'7号洞'!D130,'8号洞'!D130,'9号洞'!D130,'10号洞'!D130,'11号洞'!D130,'12号洞'!D130,'13号洞'!D130,'14号洞'!D130,'15号洞'!D130,'16号洞'!D130,'17号洞'!D130,'18号洞'!D130)/SUM('1号洞'!C130,'2号洞'!C130,'3号洞'!C130,'4号洞'!C130,'5号洞'!C130,'6号洞'!C130,'7号洞'!C130,'8号洞'!C130,'9号洞'!C130,'10号洞'!C130,'11号洞'!C130,'12号洞'!C130,'13号洞'!C130,'14号洞'!C130,'15号洞'!C130,'16号洞'!C130,'17号洞'!C130,'18号洞'!C130),"-") -> - | P7: 0-10yd平均剩余 | Q7: =IFERROR(SUM('1号洞'!F118,'2号洞'!F118,'3号洞'!F118,'4号洞'!F118,'5号洞'!F118,'6号洞'!F118,'7号洞'!F118,'8号洞'!F118,'9号洞'!F118,'10号洞'!F118,'11号洞'!F118,'12号洞'!F118,'13号洞'!F118,'14号洞'!F118,'15号洞'!F118,'16号洞'!F118,'17号洞'!F118,'18号洞'!F118)/SUM('1号洞'!D118,'2号洞'!D118,'3号洞'!D118,'4号洞'!D118,'5号洞'!D118,'6号洞'!D118,'7号洞'!D118,'8号洞'!D118,'9号洞'!D118,'10号洞'!D118,'11号洞'!D118,'12号洞'!D118,'13号洞'!D118,'14号洞'!D118,'15号洞'!D118,'16号洞'!D118,'17号洞'!D118,'18号洞'!D118),"-") -> 6 | R7: ft | U7: 15-30推进概率 | V7: =IFERROR(SUM('1号洞'!D96,'2号洞'!D96,'3号洞'!D96,'4号洞'!D96,'5号洞'!D96,'6号洞'!D96,'7号洞'!D96,'8号洞'!D96,'9号洞'!D96,'10号洞'!D96,'11号洞'!D96,'12号洞'!D96,'13号洞'!D96,'14号洞'!D96,'15号洞'!D96,'16号洞'!D96,'17号洞'!D96,'18号洞'!D96)/SUM('1号洞'!C96,'2号洞'!C96,'3号洞'!C96,'4号洞'!C96,'5号洞'!C96,'6号洞'!C96,'7号洞'!C96,'8号洞'!C96,'9号洞'!C96,'10号洞'!C96,'11号洞'!C96,'12号洞'!C96,'13号洞'!C96,'14号洞'!C96,'15号洞'!C96,'16号洞'!C96,'17号洞'!C96,'18号洞'!C96),"-") -> 0
C8: 平均开球距离 | D8: {=IFERROR(SUM('1号洞'!E89,'2号洞'!E89,'3号洞'!E89,'4号洞'!E89,'5号洞'!E89,'6号洞'!E89,'7号洞'!E89,'8号洞'!E89,'9号洞'!E89,'10号洞'!E89,'11号洞'!E89,'12号洞'!E89,'13号洞'!E89,'14号洞'!E89,'15号洞'!E89,'16号洞'!E89,'17号洞'!E89,'18号洞'!E89)/SUM('1号洞'!F89,'2号洞'!F89,'3号洞'!F89,'4号洞'!F89,'5号洞'!F89,'6号洞'!F89,'7号洞'!F89,'8号洞'!F89,'9号洞'!F89,'10号洞'!F89,'11号洞'!F89,'12号洞'!F89,'13号洞'!F89,'14号洞'!F89,'15号洞'!F89,'16号洞'!F89,'17号洞'!F89,'18号洞'!F89),“-”)} -> 192.42857 | K8: 50-75精准度 | L8: =IFERROR(SUM('1号洞'!E125,'2号洞'!E125,'3号洞'!E125,'4号洞'!E125,'5号洞'!E125,'6号洞'!E125,'7号洞'!E125,'8号洞'!E125,'9号洞'!E125,'10号洞'!E125,'11号洞'!E125,'12号洞'!E125,'13号洞'!E125,'14号洞'!E125,'15号洞'!E125,'16号洞'!E125,'17号洞'!E125,'18号洞'!E125)/SUM('1号洞'!D125,'2号洞'!D125,'3号洞'!D125,'4号洞'!D125,'5号洞'!D125,'6号洞'!D125,'7号洞'!D125,'8号洞'!D125,'9号洞'!D125,'10号洞'!D125,'11号洞'!D125,'12号洞'!D125,'13号洞'!D125,'14号洞'!D125,'15号洞'!D125,'16号洞'!D125,'17号洞'!D125,'18号洞'!D125),"-") -> 18 | M8: ft | P8: 10-20yd平均剩余 | Q8: =IFERROR(SUM('1号洞'!F119,'2号洞'!F119,'3号洞'!F119,'4号洞'!F119,'5号洞'!F119,'6号洞'!F119,'7号洞'!F119,'8号洞'!F119,'9号洞'!F119,'10号洞'!F119,'11号洞'!F119,'12号洞'!F119,'13号洞'!F119,'14号洞'!F119,'15号洞'!F119,'16号洞'!F119,'17号洞'!F119,'18号洞'!F119)/SUM('1号洞'!D119,'2号洞'!D119,'3号洞'!D119,'4号洞'!D119,'5号洞'!D119,'6号洞'!D119,'7号洞'!D119,'8号洞'!D119,'9号洞'!D119,'10号洞'!D119,'11号洞'!D119,'12号洞'!D119,'13号洞'!D119,'14号洞'!D119,'15号洞'!D119,'16号洞'!D119,'17号洞'!D119,'18号洞'!D119),"-") -> 15 | R8: ft | U8: 30以上推进概率 | V8: =IFERROR(SUM('1号洞'!D97,'2号洞'!D97,'3号洞'!D97,'4号洞'!D97,'5号洞'!D97,'6号洞'!D97,'7号洞'!D97,'8号洞'!D97,'9号洞'!D97,'10号洞'!D97,'11号洞'!D97,'12号洞'!D97,'13号洞'!D97,'14号洞'!D97,'15号洞'!D97,'16号洞'!D97,'17号洞'!D97,'18号洞'!D97)/SUM('1号洞'!C97,'2号洞'!C97,'3号洞'!C97,'4号洞'!C97,'5号洞'!C97,'6号洞'!C97,'7号洞'!C97,'8号洞'!C97,'9号洞'!C97,'10号洞'!C97,'11号洞'!C97,'12号洞'!C97,'13号洞'!C97,'14号洞'!C97,'15号洞'!C97,'16号洞'!C97,'17号洞'!C97,'18号洞'!C97),"-") -> 0
C9: 最远开球距离 | D9: =MAX('1号洞'!E89,'2号洞'!E89,'3号洞'!E89,'4号洞'!E89,'5号洞'!E89,'6号洞'!E89,'7号洞'!E89,'8号洞'!E89,'9号洞'!E89,'10号洞'!E89,'11号洞'!E89,'12号洞'!E89,'13号洞'!E89,'14号洞'!E89,'15号洞'!E89,'16号洞'!E89,'17号洞'!E89,'18号洞'!E89) -> 208 | K9: 75-100精准度 | L9: =IFERROR(SUM('1号洞'!E126,'2号洞'!E126,'3号洞'!E126,'4号洞'!E126,'5号洞'!E126,'6号洞'!E126,'7号洞'!E126,'8号洞'!E126,'9号洞'!E126,'10号洞'!E126,'11号洞'!E126,'12号洞'!E126,'13号洞'!E126,'14号洞'!E126,'15号洞'!E126,'16号洞'!E126,'17号洞'!E126,'18号洞'!E126)/SUM('1号洞'!D126,'2号洞'!D126,'3号洞'!D126,'4号洞'!D126,'5号洞'!D126,'6号洞'!D126,'7号洞'!D126,'8号洞'!D126,'9号洞'!D126,'10号洞'!D126,'11号洞'!D126,'12号洞'!D126,'13号洞'!D126,'14号洞'!D126,'15号洞'!D126,'16号洞'!D126,'17号洞'!D126,'18号洞'!D126),"-") -> 36 | M9: ft | P9: 20-30yd平均剩余 | Q9: =IFERROR(SUM('1号洞'!F120,'2号洞'!F120,'3号洞'!F120,'4号洞'!F120,'5号洞'!F120,'6号洞'!F120,'7号洞'!F120,'8号洞'!F120,'9号洞'!F120,'10号洞'!F120,'11号洞'!F120,'12号洞'!F120,'13号洞'!F120,'14号洞'!F120,'15号洞'!F120,'16号洞'!F120,'17号洞'!F120,'18号洞'!F120)/SUM('1号洞'!D120,'2号洞'!D120,'3号洞'!D120,'4号洞'!D120,'5号洞'!D120,'6号洞'!D120,'7号洞'!D120,'8号洞'!D120,'9号洞'!D120,'10号洞'!D120,'11号洞'!D120,'12号洞'!D120,'13号洞'!D120,'14号洞'!D120,'15号洞'!D120,'16号洞'!D120,'17号洞'!D120,'18号洞'!D120),"-") -> 21 | R9: ft | U9: 9-15三推概率 | V9: =IFERROR(SUM('1号洞'!E101,'2号洞'!E101,'3号洞'!E101,'4号洞'!E101,'5号洞'!E101,'6号洞'!E101,'7号洞'!E101,'8号洞'!E101,'9号洞'!E101,'10号洞'!E101,'11号洞'!E101,'12号洞'!E101,'13号洞'!E101,'14号洞'!E101,'15号洞'!E101,'16号洞'!E101,'17号洞'!E101,'18号洞'!E101)/SUM('1号洞'!C101,'2号洞'!C101,'3号洞'!C101,'4号洞'!C101,'5号洞'!C101,'6号洞'!C101,'7号洞'!C101,'8号洞'!C101,'9号洞'!C101,'10号洞'!C101,'11号洞'!C101,'12号洞'!C101,'13号洞'!C101,'14号洞'!C101,'15号洞'!C101,'16号洞'!C101,'17号洞'!C101,'18号洞'!C101),"-") -> 0
C10: 开球上球道率 | D10: {=IFERROR(SUM('1号洞'!E90+0,'2号洞'!E90+0,'3号洞'!E90+0,'4号洞'!E90+0,'5号洞'!E90+0,'6号洞'!E90+0,'7号洞'!E90+0,'8号洞'!E90+0,'9号洞'!E90+0,'10号洞'!E90+0,'11号洞'!E90+0,'12号洞'!E90+0,'13号洞'!E90+0,'14号洞'!E90+0,'15号洞'!E90+0,'16号洞'!E90+0,'17号洞'!E90+0,'18号洞'!E90+0)/SUM('1号洞'!F90,'2号洞'!F90,'3号洞'!F90,'4号洞'!F90,'5号洞'!F90,'6号洞'!F90,'7号洞'!F90,'8号洞'!F90,'9号洞'!F90,'10号洞'!F90,'11号洞'!F90,'12号洞'!F90,'13号洞'!F90,'14号洞'!F90,'15号洞'!F90,'16号洞'!F90,'17号洞'!F90,'18号洞'!F90),“-”)} -> 0.92857143 | K10: 100-125精准度 | L10: =IFERROR(SUM('1号洞'!E127,'2号洞'!E127,'3号洞'!E127,'4号洞'!E127,'5号洞'!E127,'6号洞'!E127,'7号洞'!E127,'8号洞'!E127,'9号洞'!E127,'10号洞'!E127,'11号洞'!E127,'12号洞'!E127,'13号洞'!E127,'14号洞'!E127,'15号洞'!E127,'16号洞'!E127,'17号洞'!E127,'18号洞'!E127)/SUM('1号洞'!D127,'2号洞'!D127,'3号洞'!D127,'4号洞'!D127,'5号洞'!D127,'6号洞'!D127,'7号洞'!D127,'8号洞'!D127,'9号洞'!D127,'10号洞'!D127,'11号洞'!D127,'12号洞'!D127,'13号洞'!D127,'14号洞'!D127,'15号洞'!D127,'16号洞'!D127,'17号洞'!D127,'18号洞'!D127),"-") -> 12 | M10: ft | P10: 30-40yd平均剩余 | Q10: =IFERROR(SUM('1号洞'!F121,'2号洞'!F121,'3号洞'!F121,'4号洞'!F121,'5号洞'!F121,'6号洞'!F121,'7号洞'!F121,'8号洞'!F121,'9号洞'!F121,'10号洞'!F121,'11号洞'!F121,'12号洞'!F121,'13号洞'!F121,'14号洞'!F121,'15号洞'!F121,'16号洞'!F121,'17号洞'!F121,'18号洞'!F121)/SUM('1号洞'!D121,'2号洞'!D121,'3号洞'!D121,'4号洞'!D121,'5号洞'!D121,'6号洞'!D121,'7号洞'!D121,'8号洞'!D121,'9号洞'!D121,'10号洞'!D121,'11号洞'!D121,'12号洞'!D121,'13号洞'!D121,'14号洞'!D121,'15号洞'!D121,'16号洞'!D121,'17号洞'!D121,'18号洞'!D121),"-") -> 34.5 | R10: ft | U10: 15-30三推概率 | V10: =IFERROR(SUM('1号洞'!E102,'2号洞'!E102,'3号洞'!E102,'4号洞'!E102,'5号洞'!E102,'6号洞'!E102,'7号洞'!E102,'8号洞'!E102,'9号洞'!E102,'10号洞'!E102,'11号洞'!E102,'12号洞'!E102,'13号洞'!E102,'14号洞'!E102,'15号洞'!E102,'16号洞'!E102,'17号洞'!E102,'18号洞'!E102)/SUM('1号洞'!C102,'2号洞'!C102,'3号洞'!C102,'4号洞'!C102,'5号洞'!C102,'6号洞'!C102,'7号洞'!C102,'8号洞'!C102,'9号洞'!C102,'10号洞'!C102,'11号洞'!C102,'12号洞'!C102,'13号洞'!C102,'14号洞'!C102,'15号洞'!C102,'16号洞'!C102,'17号洞'!C102,'18号洞'!C102),"-") -> 0
C11: 三杆洞平均成绩 | D11: {=IFERROR(SUM('1号洞'!B133,'2号洞'!B133,'3号洞'!B133,'4号洞'!B133,'5号洞'!B133,'6号洞'!B133,'7号洞'!B133,'8号洞'!B133,'9号洞'!B133,'10号洞'!B133,'11号洞'!B133,'12号洞'!B133,'13号洞'!B133,'14号洞'!B133,'15号洞'!B133,'16号洞'!B133,'17号洞'!B133,'18号洞'!B133)/SUM('1号洞'!C133,'2号洞'!C133,'3号洞'!C133,'4号洞'!C133,'5号洞'!C133,'6号洞'!C133,'7号洞'!C133,'8号洞'!C133,'9号洞'!C133,'10号洞'!C133,'11号洞'!C133,'12号洞'!C133,'13号洞'!C133,'14号洞'!C133,'15号洞'!C133,'16号洞'!C133,'17号洞'!C133,'18号洞'!C133),“-”)} -> 3.25 | K11: 125-150精准度 | L11: =IFERROR(SUM('1号洞'!E128,'2号洞'!E128,'3号洞'!E128,'4号洞'!E128,'5号洞'!E128,'6号洞'!E128,'7号洞'!E128,'8号洞'!E128,'9号洞'!E128,'10号洞'!E128,'11号洞'!E128,'12号洞'!E128,'13号洞'!E128,'14号洞'!E128,'15号洞'!E128,'16号洞'!E128,'17号洞'!E128,'18号洞'!E128)/SUM('1号洞'!D128,'2号洞'!D128,'3号洞'!D128,'4号洞'!D128,'5号洞'!D128,'6号洞'!D128,'7号洞'!D128,'8号洞'!D128,'9号洞'!D128,'10号洞'!D128,'11号洞'!D128,'12号洞'!D128,'13号洞'!D128,'14号洞'!D128,'15号洞'!D128,'16号洞'!D128,'17号洞'!D128,'18号洞'!D128),"-") -> 30 | M11: ft | P11: 40-50yd平均剩余 | Q11: =IFERROR(SUM('1号洞'!F122,'2号洞'!F122,'3号洞'!F122,'4号洞'!F122,'5号洞'!F122,'6号洞'!F122,'7号洞'!F122,'8号洞'!F122,'9号洞'!F122,'10号洞'!F122,'11号洞'!F122,'12号洞'!F122,'13号洞'!F122,'14号洞'!F122,'15号洞'!F122,'16号洞'!F122,'17号洞'!F122,'18号洞'!F122)/SUM('1号洞'!D122,'2号洞'!D122,'3号洞'!D122,'4号洞'!D122,'5号洞'!D122,'6号洞'!D122,'7号洞'!D122,'8号洞'!D122,'9号洞'!D122,'10号洞'!D122,'11号洞'!D122,'12号洞'!D122,'13号洞'!D122,'14号洞'!D122,'15号洞'!D122,'16号洞'!D122,'17号洞'!D122,'18号洞'!D122),"-") -> 18 | R11: ft | U11: 30以上三推概率 | V11: =IFERROR(SUM('1号洞'!E103,'2号洞'!E103,'3号洞'!E103,'4号洞'!E103,'5号洞'!E103,'6号洞'!E103,'7号洞'!E103,'8号洞'!E103,'9号洞'!E103,'10号洞'!E103,'11号洞'!E103,'12号洞'!E103,'13号洞'!E103,'14号洞'!E103,'15号洞'!E103,'16号洞'!E103,'17号洞'!E103,'18号洞'!E103)/SUM('1号洞'!C103,'2号洞'!C103,'3号洞'!C103,'4号洞'!C103,'5号洞'!C103,'6号洞'!C103,'7号洞'!C103,'8号洞'!C103,'9号洞'!C103,'10号洞'!C103,'11号洞'!C103,'12号洞'!C103,'13号洞'!C103,'14号洞'!C103,'15号洞'!C103,'16号洞'!C103,'17号洞'!C103,'18号洞'!C103),"-") -> 0.5
C12: 四杆洞平均成绩 | D12: {=IFERROR(SUM('1号洞'!B134,'2号洞'!B134,'3号洞'!B134,'4号洞'!B134,'5号洞'!B134,'6号洞'!B134,'7号洞'!B134,'8号洞'!B134,'9号洞'!B134,'10号洞'!B134,'11号洞'!B134,'12号洞'!B134,'13号洞'!B134,'14号洞'!B134,'15号洞'!B134,'16号洞'!B134,'17号洞'!B134,'18号洞'!B134)/SUM('1号洞'!C134,'2号洞'!C134,'3号洞'!C134,'4号洞'!C134,'5号洞'!C134,'6号洞'!C134,'7号洞'!C134,'8号洞'!C134,'9号洞'!C134,'10号洞'!C134,'11号洞'!C134,'12号洞'!C134,'13号洞'!C134,'14号洞'!C134,'15号洞'!C134,'16号洞'!C134,'17号洞'!C134,'18号洞'!C134),“-”)} -> 4.7 | K12: 150-200精准度 | L12: =IFERROR(SUM('1号洞'!E129,'2号洞'!E129,'3号洞'!E129,'4号洞'!E129,'5号洞'!E129,'6号洞'!E129,'7号洞'!E129,'8号洞'!E129,'9号洞'!E129,'10号洞'!E129,'11号洞'!E129,'12号洞'!E129,'13号洞'!E129,'14号洞'!E129,'15号洞'!E129,'16号洞'!E129,'17号洞'!E129,'18号洞'!E129)/SUM('1号洞'!D129,'2号洞'!D129,'3号洞'!D129,'4号洞'!D129,'5号洞'!D129,'6号洞'!D129,'7号洞'!D129,'8号洞'!D129,'9号洞'!D129,'10号洞'!D129,'11号洞'!D129,'12号洞'!D129,'13号洞'!D129,'14号洞'!D129,'15号洞'!D129,'16号洞'!D129,'17号洞'!D129,'18号洞'!D129),"-") -> - | M12: ft | P12: 沙坑救球平均剩余 | Q12: =IFERROR(SUM('1号洞'!H118:H122,'2号洞'!H118:H122,'3号洞'!H118:H122,'4号洞'!H118:H122,'5号洞'!H118:H122,'6号洞'!H118:H122,'7号洞'!H118:H122,'8号洞'!H118:H122,'9号洞'!H118:H122,'10号洞'!H118:H122,'11号洞'!H118:H122,'12号洞'!H118:H122,'13号洞'!H118:H122,'14号洞'!H118:H122,'15号洞'!H118:H122,'16号洞'!H118:H122,'17号洞'!H118:H122,'18号洞'!H118:H122)/SUM('1号洞'!G118:G122,'2号洞'!G118:G122,'3号洞'!G118:G122,'4号洞'!G118:G122,'5号洞'!G118:G122,'6号洞'!G118:G122,'7号洞'!G118:G122,'8号洞'!G118:G122,'9号洞'!G118:G122,'10号洞'!G118:G122,'11号洞'!G118:G122,'12号洞'!G118:G122,'13号洞'!G118:G122,'14号洞'!G118:G122,'15号洞'!G118:G122,'16号洞'!G118:G122,'17号洞'!G118:G122,'18号洞'!G118:G122),"-") -> - | R12: ft
C13: 五杆洞平均成绩 | D13: {=IFERROR(SUM('1号洞'!B135,'2号洞'!B135,'3号洞'!B135,'4号洞'!B135,'5号洞'!B135,'6号洞'!B135,'7号洞'!B135,'8号洞'!B135,'9号洞'!B135,'10号洞'!B135,'11号洞'!B135,'12号洞'!B135,'13号洞'!B135,'14号洞'!B135,'15号洞'!B135,'16号洞'!B135,'17号洞'!B135,'18号洞'!B135)/SUM('1号洞'!C135,'2号洞'!C135,'3号洞'!C135,'4号洞'!C135,'5号洞'!C135,'6号洞'!C135,'7号洞'!C135,'8号洞'!C135,'9号洞'!C135,'10号洞'!C135,'11号洞'!C135,'12号洞'!C135,'13号洞'!C135,'14号洞'!C135,'15号洞'!C135,'16号洞'!C135,'17号洞'!C135,'18号洞'!C135),“-”)} -> 5.25 | K13: 200以上精准度 | L13: =IFERROR(SUM('1号洞'!E130,'2号洞'!E130,'3号洞'!E130,'4号洞'!E130,'5号洞'!E130,'6号洞'!E130,'7号洞'!E130,'8号洞'!E130,'9号洞'!E130,'10号洞'!E130,'11号洞'!E130,'12号洞'!E130,'13号洞'!E130,'14号洞'!E130,'15号洞'!E130,'16号洞'!E130,'17号洞'!E130,'18号洞'!E130)/SUM('1号洞'!D130,'2号洞'!D130,'3号洞'!D130,'4号洞'!D130,'5号洞'!D130,'6号洞'!D130,'7号洞'!D130,'8号洞'!D130,'9号洞'!D130,'10号洞'!D130,'11号洞'!D130,'12号洞'!D130,'13号洞'!D130,'14号洞'!D130,'15号洞'!D130,'16号洞'!D130,'17号洞'!D130,'18号洞'!D130),"-") -> - | M13: ft
C14: Eagle | D14: =SUM('1号洞'!B136,'2号洞'!B136,'3号洞'!B136,'4号洞'!B136,'5号洞'!B136,'6号洞'!B136,'7号洞'!B136,'8号洞'!B136,'9号洞'!B136,'10号洞'!B136,'11号洞'!B136,'12号洞'!B136,'13号洞'!B136,'14号洞'!B136,'15号洞'!B136,'16号洞'!B136,'17号洞'!B136,'18号洞'!B136) -> 0
C15: Birdies | D15: =SUM('1号洞'!B137,'2号洞'!B137,'3号洞'!B137,'4号洞'!B137,'5号洞'!B137,'6号洞'!B137,'7号洞'!B137,'8号洞'!B137,'9号洞'!B137,'10号洞'!B137,'11号洞'!B137,'12号洞'!B137,'13号洞'!B137,'14号洞'!B137,'15号洞'!B137,'16号洞'!B137,'17号洞'!B137,'18号洞'!B137) -> 1
C16: Par | D16: =SUM('1号洞'!B138,'2号洞'!B138,'3号洞'!B138,'4号洞'!B138,'5号洞'!B138,'6号洞'!B138,'7号洞'!B138,'8号洞'!B138,'9号洞'!B138,'10号洞'!B138,'11号洞'!B138,'12号洞'!B138,'13号洞'!B138,'14号洞'!B138,'15号洞'!B138,'16号洞'!B138,'17号洞'!B138,'18号洞'!B138) -> 8
C17: Bogey | D17: =SUM('1号洞'!B139,'2号洞'!B139,'3号洞'!B139,'4号洞'!B139,'5号洞'!B139,'6号洞'!B139,'7号洞'!B139,'8号洞'!B139,'9号洞'!B139,'10号洞'!B139,'11号洞'!B139,'12号洞'!B139,'13号洞'!B139,'14号洞'!B139,'15号洞'!B139,'16号洞'!B139,'17号洞'!B139,'18号洞'!B139) -> 8
C18: Double Bogey | D18: =SUM('1号洞'!B140,'2号洞'!B140,'3号洞'!B140,'4号洞'!B140,'5号洞'!B140,'6号洞'!B140,'7号洞'!B140,'8号洞'!B140,'9号洞'!B140,'10号洞'!B140,'11号洞'!B140,'12号洞'!B140,'13号洞'!B140,'14号洞'!B140,'15号洞'!B140,'16号洞'!B140,'17号洞'!B140,'18号洞'!B140) -> 1

Sheet 1号洞
B2: 标准杆 | C2: 4 | D2: 杆
B3: 成绩 | C3: 6 | D3: 杆
B5: 挥杆&切杆 | E5: 推杆
B6: 第一杆 | C6: 1号木 | E6: 第一推
B7: 距离： | C7: 361 | D7: yd | E7: 距离： | F7: 51 | G7: ft
B8: 方向： | C8: 偏右 | E8: 第二推
B9: 球位 | C9: 球道 | E9: 距离： | F9: 6 | G9: ft
B10: 是否直攻 | C10: 过渡 | E10: 第三推
B11: 罚杆 | C11: 0 | D11: 杆 | E11: 距离： | F11: 1 | G11: ft
B12: 第二杆 | C12: 7铁 | E12: 第四推
B13: 距离： | C13: 156 | D13: yd | E13: 距离： | G13: ft
B14: 方向： | C14: 偏右 | E14: 第五推
B15: 球位 | C15: 球道 | E15: 距离： | G15: ft
B16: 是否直攻 | C16: 直攻 | E16: 第六推
B17: 罚杆 | C17: 0 | D17: 杆 | E17: 距离： | G17: ft
B18: 第三杆 | C18: 56度 | E18: 第七推
B19: 距离： | C19: 31 | D19: yd | E19: 距离： | G19: ft
B20: 方向： | C20: 直球 | E20: 第8推
B21: 球位 | C21: 长草 | E21: 距离： | G21: ft
B22: 是否直攻 | C22: 直攻
B23: 罚杆 | C23: 0 | D23: 杆 | E23: 额外罚杆 | G23: 杆
B24: 第四杆
B25: 距离： | D25: yd
B26: 方向：
B27: 球位
B28: 是否直攻
B29: 罚杆 | D29: 杆
B30: 第五杆
B31: 距离： | D31: yd
B32: 方向：
B33: 球位
B34: 是否直攻
B35: 罚杆 | D35: 杆
B36: 第六杆
B37: 距离： | D37: yd
B38: 方向：
B39: 球位
B40: 是否直攻
B41: 罚杆 | D41: 杆
B42: 第七杆
...

Sheet 2号洞
B2: 标准杆 | C2: 5 | D2: 杆
B3: 成绩 | C3: 5 | D3: 杆
B5: 挥杆&切杆 | E5: 推杆
B6: 第一杆 | C6: 1号木 | E6: 第一推
B7: 距离： | C7: 475 | D7: yd | E7: 距离： | F7: 6 | G7: ft
B8: 方向： | C8: 偏右 | E8: 第二推
B9: 球位 | C9: 沙坑 | E9: 距离： | G9: ft
B10: 是否直攻 | C10: 过渡 | E10: 第三推
B11: 罚杆 | C11: 0 | D11: 杆 | E11: 距离： | G11: ft
B12: 第二杆 | C12: 球道木 | E12: 第四推
B13: 距离： | C13: 300 | D13: yd | E13: 距离： | G13: ft
B14: 方向： | C14: 直球 | E14: 第五推
B15: 球位 | C15: 球道 | E15: 距离： | G15: ft
B16: 是否直攻 | C16: 过渡 | E16: 第六推
B17: 罚杆 | C17: 0 | D17: 杆 | E17: 距离： | G17: ft
B18: 第三杆 | C18: 球道木 | E18: 第七推
B19: 距离： | C19: 200 | D19: yd | E19: 距离： | G19: ft
B20: 方向： | C20: 偏右 | E20: 第8推
B21: 球位 | C21: 球道 | E21: 距离： | G21: ft
B22: 是否直攻 | C22: 过渡
B23: 罚杆 | C23: 0 | D23: 杆 | E23: 额外罚杆 | G23: 杆
B24: 第四杆 | C24: 56度
B25: 距离： | C25: 99 | D25: yd
B26: 方向： | C26: 直球
B27: 球位 | C27: 球道
B28: 是否直攻 | C28: 直攻
B29: 罚杆 | C29: 0 | D29: 杆
B30: 第五杆
B31: 距离： | D31: yd
B32: 方向：
B33: 球位
B34: 是否直攻
B35: 罚杆 | D35: 杆
B36: 第六杆
B37: 距离： | D37: yd
B38: 方向：
B39: 球位
B40: 是否直攻
B41: 罚杆 | D41: 杆
B42: 第七杆
...

Sheet 3号洞
B2: 标准杆 | C2: 4 | D2: 杆
B3: 成绩 | C3: 4 | D3: 杆
B5: 挥杆&切杆 | E5: 推杆
B6: 第一杆 | C6: 1号木 | E6: 第一推
B7: 距离： | C7: 298 | D7: yd | E7: 距离： | F7: 66 | G7: ft
B8: 方向： | C8: 直球 | E8: 第二推
B9: 球位 | C9: 球道 | E9: 距离： | F9: 6 | G9: ft
B10: 是否直攻 | C10: 过渡 | E10: 第三推
B11: 罚杆 | C11: 0 | D11: 杆 | E11: 距离： | G11: ft
B12: 第二杆 | C12: 7铁 | E12: 第四推
B13: 距离： | C13: 115 | D13: yd | E13: 距离： | G13: ft
B14: 方向： | C14: 偏右 | E14: 第五推
B15: 球位 | C15: 球道 | E15: 距离： | G15: ft
B16: 是否直攻 | C16: 直攻 | E16: 第六推
B17: 罚杆 | C17: 0 | D17: 杆 | E17: 距离： | G17: ft
B18: 第三杆 | E18: 第七推
B19: 距离： | D19: yd | E19: 距离： | G19: ft
B20: 方向： | E20: 第8推
B21: 球位 | E21: 距离： | G21: ft
B22: 是否直攻
B23: 罚杆 | D23: 杆 | E23: 额外罚杆 | G23: 杆
B24: 第四杆
B25: 距离： | D25: yd
B26: 方向：
B27: 球位
B28: 是否直攻
B29: 罚杆 | D29: 杆
B30: 第五杆
B31: 距离： | D31: yd
B32: 方向：
B33: 球位
B34: 是否直攻
B35: 罚杆 | D35: 杆
B36: 第六杆
B37: 距离： | D37: yd
B38: 方向：
B39: 球位
B40: 是否直攻
B41: 罚杆 | D41: 杆
B42: 第七杆
...

Sheet 4号洞
B2: 标准杆 | C2: 5 | D2: 杆
B3: 成绩 | C3: 6 | D3: 杆
B5: 挥杆&切杆 | E5: 推杆
B6: 第一杆 | C6: 1号木 | E6: 第一推
B7: 距离： | C7: 478 | D7: yd | E7: 距离： | F7: 15 | G7: ft
B8: 方向： | C8: 偏右 | E8: 第二推
B9: 球位 | C9: 球道 | E9: 距离： | F9: 2 | G9: ft
B10: 是否直攻 | C10: 过渡 | E10: 第三推
B11: 罚杆 | C11: 0 | D11: 杆 | E11: 距离： | G11: ft
B12: 第二杆 | C12: 球道木 | E12: 第四推
B13: 距离： | C13: 290 | D13: yd | E13: 距离： | G13: ft
B14: 方向： | C14: 直球 | E14: 第五推
B15: 球位 | C15: 球道 | E15: 距离： | G15: ft
B16: 是否直攻 | C16: 过渡 | E16: 第六推
B17: 罚杆 | C17: 0 | D17: 杆 | E17: 距离： | G17: ft
B18: 第三杆 | C18: 7铁 | E18: 第七推
B19: 距离： | C19: 110 | D19: yd | E19: 距离： | G19: ft
B20: 方向： | C20: 直球 | E20: 第8推
B21: 球位 | C21: 球道 | E21: 距离： | G21: ft
B22: 是否直攻 | C22: 直攻
B23: 罚杆 | C23: 0 | D23: 杆 | E23: 额外罚杆 | G23: 杆
B24: 第四杆 | C24: 56度
B25: 距离： | C25: 49 | D25: yd
B26: 方向： | C26: 直球
B27: 球位 | C27: 球道
B28: 是否直攻 | C28: 直攻
B29: 罚杆 | C29: 0 | D29: 杆
B30: 第五杆
B31: 距离： | D31: yd
B32: 方向：
B33: 球位
B34: 是否直攻
B35: 罚杆 | D35: 杆
B36: 第六杆
B37: 距离： | D37: yd
B38: 方向：
B39: 球位
B40: 是否直攻
B41: 罚杆 | D41: 杆
B42: 第七杆
...

Sheet 5号洞
B2: 标准杆 | C2: 3 | D2: 杆
B3: 成绩 | C3: 3 | D3: 杆
B5: 挥杆&切杆 | E5: 推杆
B6: 第一杆 | C6: 7铁 | E6: 第一推
B7: 距离： | C7: 126 | D7: yd | E7: 距离： | F7: 6 | G7: ft
B8: 方向： | C8: 直球 | E8: 第二推
B9: 球位 | C9: 球道 | E9: 距离： | G9: ft
B10: 是否直攻 | C10: 直攻 | E10: 第三推
B11: 罚杆 | C11: 0 | D11: 杆 | E11: 距离： | G11: ft
B12: 第二杆 | C12: 56度 | E12: 第四推
B13: 距离： | C13: 10 | D13: yd | E13: 距离： | G13: ft
B14: 方向： | C14: 直球 | E14: 第五推
B15: 球位 | C15: 球道 | E15: 距离： | G15: ft
B16: 是否直攻 | C16: 直攻 | E16: 第六推
B17: 罚杆 | C17: 0 | D17: 杆 | E17: 距离： | G17: ft
B18: 第三杆 | E18: 第七推
B19: 距离： | D19: yd | E19: 距离： | G19: ft
B20: 方向： | E20: 第8推
B21: 球位 | E21: 距离： | G21: ft
B22: 是否直攻
B23: 罚杆 | D23: 杆 | E23: 额外罚杆 | G23: 杆
B24: 第四杆
B25: 距离： | D25: yd
B26: 方向：
B27: 球位
B28: 是否直攻
B29: 罚杆 | D29: 杆
B30: 第五杆
B31: 距离： | D31: yd
B32: 方向：
B33: 球位
B34: 是否直攻
B35: 罚杆 | D35: 杆
B36: 第六杆
B37: 距离： | D37: yd
B38: 方向：
B39: 球位
B40: 是否直攻
B41: 罚杆 | D41: 杆
B42: 第七杆
...

Sheet 6号洞
B2: 标准杆 | C2: 4 | D2: 杆
B3: 成绩 | C3: 4 | D3: 杆
B5: 挥杆&切杆 | E5: 推杆
B6: 第一杆 | C6: 1号木 | E6: 第一推
B7: 距离： | C7: 298 | D7: yd | E7: 距离： | F7: 27 | G7: ft
B8: 方向： | C8: 直球 | E8: 第二推
B9: 球位 | C9: 球道 | E9: 距离： | F9: 4 | G9: ft
B10: 是否直攻 | C10: 过渡 | E10: 第三推
B11: 罚杆 | C11: 0 | D11: 杆 | E11: 距离： | G11: ft
B12: 第二杆 | C12: 7铁 | E12: 第四推
B13: 距离： | C13: 103 | D13: yd | E13: 距离： | G13: ft
B14: 方向： | C14: 直球 | E14: 第五推
B15: 球位 | C15: 球道 | E15: 距离： | G15: ft
B16: 是否直攻 | C16: 直攻 | E16: 第六推
B17: 罚杆 | C17: 0 | D17: 杆 | E17: 距离： | G17: ft
B18: 第三杆 | E18: 第七推
B19: 距离： | D19: yd | E19: 距离： | G19: ft
B20: 方向： | E20: 第8推
B21: 球位 | E21: 距离： | G21: ft
B22: 是否直攻
B23: 罚杆 | D23: 杆 | E23: 额外罚杆 | G23: 杆
B24: 第四杆
B25: 距离： | D25: yd
B26: 方向：
B27: 球位
B28: 是否直攻
B29: 罚杆 | D29: 杆
B30: 第五杆
B31: 距离： | D31: yd
B32: 方向：
B33: 球位
B34: 是否直攻
B35: 罚杆 | D35: 杆
B36: 第六杆
B37: 距离： | D37: yd
B38: 方向：
B39: 球位
B40: 是否直攻
B41: 罚杆 | D41: 杆
B42: 第七杆
...

Sheet 7号洞
B2: 标准杆 | C2: 3 | D2: 杆
B3: 成绩 | C3: 4 | D3: 杆
B5: 挥杆&切杆 | E5: 推杆
B6: 第一杆 | C6: 7铁 | E6: 第一推
B7: 距离： | C7: 144 | D7: yd | E7: 距离： | F7: 18 | G7: ft
B8: 方向： | C8: 偏左 | E8: 第二推
B9: 球位 | C9: 球道 | E9: 距离： | F9: 2 | G9: ft
B10: 是否直攻 | C10: 直攻 | E10: 第三推
B11: 罚杆 | C11: 0 | D11: 杆 | E11: 距离： | G11: ft
B12: 第二杆 | C12: 56度 | E12: 第四推
B13: 距离： | C13: 31 | D13: yd | E13: 距离： | G13: ft
B14: 方向： | C14: 直球 | E14: 第五推
B15: 球位 | C15: 球道 | E15: 距离： | G15: ft
B16: 是否直攻 | C16: 直攻 | E16: 第六推
B17: 罚杆 | C17: 0 | D17: 杆 | E17: 距离： | G17: ft
B18: 第三杆 | E18: 第七推
B19: 距离： | D19: yd | E19: 距离： | G19: ft
B20: 方向： | E20: 第8推
B21: 球位 | E21: 距离： | G21: ft
B22: 是否直攻
B23: 罚杆 | D23: 杆 | E23: 额外罚杆 | G23: 杆
B24: 第四杆
B25: 距离： | D25: yd
B26: 方向：
B27: 球位
B28: 是否直攻
B29: 罚杆 | D29: 杆
B30: 第五杆
B31: 距离： | D31: yd
B32: 方向：
B33: 球位
B34: 是否直攻
B35: 罚杆 | D35: 杆
B36: 第六杆
B37: 距离： | D37: yd
B38: 方向：
B39: 球位
B40: 是否直攻
B41: 罚杆 | D41: 杆
B42: 第七杆
...

Sheet 8号洞
B2: 标准杆 | C2: 4 | D2: 杆
B3: 成绩 | C3: 5 | D3: 杆
B5: 挥杆&切杆 | E5: 推杆
B6: 第一杆 | C6: 1号木 | E6: 第一推
B7: 距离： | C7: 383 | D7: yd | E7: 距离： | F7: 21 | G7: ft
B8: 方向： | C8: 直球 | E8: 第二推
B9: 球位 | C9: 球道 | E9: 距离： | F9: 2 | G9: ft
B10: 是否直攻 | C10: 过渡 | E10: 第三推
B11: 罚杆 | C11: 0 | D11: 杆 | E11: 距离： | G11: ft
B12: 第二杆 | C12: 球道木 | E12: 第四推
B13: 距离： | C13: 180 | D13: yd | E13: 距离： | G13: ft
B14: 方向： | C14: 直球 | E14: 第五推
B15: 球位 | C15: 球道 | E15: 距离： | G15: ft
B16: 是否直攻 | C16: 直攻 | E16: 第六推
B17: 罚杆 | C17: 0 | D17: 杆 | E17: 距离： | G17: ft
B18: 第三杆 | C18: 56度 | E18: 第七推
B19: 距离： | C19: 25 | D19: yd | E19: 距离： | G19: ft
B20: 方向： | C20: 直球 | E20: 第8推
B21: 球位 | C21: 长草 | E21: 距离： | G21: ft
B22: 是否直攻 | C22: 直攻
B23: 罚杆 | C23: 0 | D23: 杆 | E23: 额外罚杆 | G23: 杆
B24: 第四杆
B25: 距离： | D25: yd
B26: 方向：
B27: 球位
B28: 是否直攻
B29: 罚杆 | D29: 杆
B30: 第五杆
B31: 距离： | D31: yd
B32: 方向：
B33: 球位
B34: 是否直攻
B35: 罚杆 | D35: 杆
B36: 第六杆
B37: 距离： | D37: yd
B38: 方向：
B39: 球位
B40: 是否直攻
B41: 罚杆 | D41: 杆
B42: 第七杆
...

Sheet 9号洞
B2: 标准杆 | C2: 4 | D2: 杆
B3: 成绩 | C3: 5 | D3: 杆
B5: 挥杆&切杆 | E5: 推杆
B6: 第一杆 | C6: 1号木 | E6: 第一推
B7: 距离： | C7: 373 | D7: yd | E7: 距离： | F7: 24 | G7: ft
B8: 方向： | C8: 直球 | E8: 第二推
B9: 球位 | C9: 球道 | E9: 距离： | F9: 5 | G9: ft
B10: 是否直攻 | C10: 过渡 | E10: 第三推
B11: 罚杆 | C11: 0 | D11: 杆 | E11: 距离： | G11: ft
B12: 第二杆 | C12: 球道木 | E12: 第四推
B13: 距离： | C13: 170 | D13: yd | E13: 距离： | G13: ft
B14: 方向： | C14: 直球 | E14: 第五推
B15: 球位 | C15: 球道 | E15: 距离： | G15: ft
B16: 是否直攻 | C16: 直攻 | E16: 第六推
B17: 罚杆 | C17: 0 | D17: 杆 | E17: 距离： | G17: ft
B18: 第三杆 | C18: 56度 | E18: 第七推
B19: 距离： | C19: 50 | D19: yd | E19: 距离： | G19: ft
B20: 方向： | C20: 直球 | E20: 第8推
B21: 球位 | C21: 球道 | E21: 距离： | G21: ft
B22: 是否直攻 | C22: 直攻
B23: 罚杆 | C23: 0 | D23: 杆 | E23: 额外罚杆 | G23: 杆
B24: 第四杆
B25: 距离： | D25: yd
B26: 方向：
B27: 球位
B28: 是否直攻
B29: 罚杆 | D29: 杆
B30: 第五杆
B31: 距离： | D31: yd
B32: 方向：
B33: 球位
B34: 是否直攻
B35: 罚杆 | D35: 杆
B36: 第六杆
B37: 距离： | D37: yd
B38: 方向：
B39: 球位
B40: 是否直攻
B41: 罚杆 | D41: 杆
B42: 第七杆
...

Sheet 10号洞
B2: 标准杆 | C2: 5 | D2: 杆
B3: 成绩 | C3: 4 | D3: 杆
B5: 挥杆&切杆 | E5: 推杆
B6: 第一杆 | C6: 1号木 | E6: 第一推
B7: 距离： | C7: 473 | D7: yd | E7: 距离： | F7: 15 | G7: ft
B8: 方向： | C8: 直球 | E8: 第二推
B9: 球位 | C9: 球道 | E9: 距离： | G9: ft
B10: 是否直攻 | C10: 过渡 | E10: 第三推
B11: 罚杆 | C11: 0 | D11: 杆 | E11: 距离： | G11: ft
B12: 第二杆 | C12: 球道木 | E12: 第四推
B13: 距离： | C13: 300 | D13: yd | E13: 距离： | G13: ft
B14: 方向： | C14: 直球 | E14: 第五推
B15: 球位 | C15: 球道 | E15: 距离： | G15: ft
B16: 是否直攻 | C16: 过渡 | E16: 第六推
B17: 罚杆 | C17: 0 | D17: 杆 | E17: 距离： | G17: ft
B18: 第三杆 | C18: 56度 | E18: 第七推
B19: 距离： | C19: 50 | D19: yd | E19: 距离： | G19: ft
B20: 方向： | C20: 直球 | E20: 第8推
B21: 球位 | C21: 球道 | E21: 距离： | G21: ft
B22: 是否直攻 | C22: 直攻
B23: 罚杆 | C23: 0 | D23: 杆 | E23: 额外罚杆 | G23: 杆
B24: 第四杆
B25: 距离： | D25: yd
B26: 方向：
B27: 球位
B28: 是否直攻
B29: 罚杆 | D29: 杆
B30: 第五杆
B31: 距离： | D31: yd
B32: 方向：
B33: 球位
B34: 是否直攻
B35: 罚杆 | D35: 杆
B36: 第六杆
B37: 距离： | D37: yd
B38: 方向：
B39: 球位
B40: 是否直攻
B41: 罚杆 | D41: 杆
B42: 第七杆
...

Sheet 11号洞
B2: 标准杆 | C2: 4 | D2: 杆
B3: 成绩 | C3: 4 | D3: 杆
B5: 挥杆&切杆 | E5: 推杆
B6: 第一杆 | C6: 1号木 | E6: 第一推
B7: 距离： | C7: 287 | D7: yd | E7: 距离： | F7: 15 | G7: ft
B8: 方向： | C8: 偏右 | E8: 第二推
B9: 球位 | C9: 球道 | E9: 距离： | F9: 2 | G9: ft
B10: 是否直攻 | C10: 过渡 | E10: 第三推
B11: 罚杆 | C11: 0 | D11: 杆 | E11: 距离： | G11: ft
B12: 第二杆 | C12: 7铁 | E12: 第四推
B13: 距离： | C13: 100 | D13: yd | E13: 距离： | G13: ft
B14: 方向： | C14: 直球 | E14: 第五推
B15: 球位 | C15: 球道 | E15: 距离： | G15: ft
B16: 是否直攻 | C16: 直攻 | E16: 第六推
B17: 罚杆 | C17: 0 | D17: 杆 | E17: 距离： | G17: ft
B18: 第三杆 | E18: 第七推
B19: 距离： | D19: yd | E19: 距离： | G19: ft
B20: 方向： | E20: 第8推
B21: 球位 | E21: 距离： | G21: ft
B22: 是否直攻
B23: 罚杆 | D23: 杆 | E23: 额外罚杆 | G23: 杆
B24: 第四杆
B25: 距离： | D25: yd
B26: 方向：
B27: 球位
B28: 是否直攻
B29: 罚杆 | D29: 杆
B30: 第五杆
B31: 距离： | D31: yd
B32: 方向：
B33: 球位
B34: 是否直攻
B35: 罚杆 | D35: 杆
B36: 第六杆
B37: 距离： | D37: yd
B38: 方向：
B39: 球位
B40: 是否直攻
B41: 罚杆 | D41: 杆
B42: 第七杆
...

Sheet 12号洞
B2: 标准杆 | C2: 4 | D2: 杆
B3: 成绩 | C3: 4 | D3: 杆
B5: 挥杆&切杆 | E5: 推杆
B6: 第一杆 | C6: 1号木 | E6: 第一推
B7: 距离： | C7: 378 | D7: yd | E7: 距离： | F7: 6 | G7: ft
B8: 方向： | C8: 直球 | E8: 第二推
B9: 球位 | C9: 球道 | E9: 距离： | G9: ft
B10: 是否直攻 | C10: 过渡 | E10: 第三推
B11: 罚杆 | C11: 0 | D11: 杆 | E11: 距离： | G11: ft
B12: 第二杆 | C12: 球道木 | E12: 第四推
B13: 距离： | C13: 170 | D13: yd | E13: 距离： | G13: ft
B14: 方向： | C14: 直球 | E14: 第五推
B15: 球位 | C15: 球道 | E15: 距离： | G15: ft
B16: 是否直攻 | C16: 直攻 | E16: 第六推
B17: 罚杆 | C17: 0 | D17: 杆 | E17: 距离： | G17: ft
B18: 第三杆 | C18: 56度 | E18: 第七推
B19: 距离： | C19: 8 | D19: yd | E19: 距离： | G19: ft
B20: 方向： | C20: 直球 | E20: 第8推
B21: 球位 | C21: 球道 | E21: 距离： | G21: ft
B22: 是否直攻 | C22: 直攻
B23: 罚杆 | C23: 0 | D23: 杆 | E23: 额外罚杆 | G23: 杆
B24: 第四杆
B25: 距离： | D25: yd
B26: 方向：
B27: 球位
B28: 是否直攻
B29: 罚杆 | D29: 杆
B30: 第五杆
B31: 距离： | D31: yd
B32: 方向：
B33: 球位
B34: 是否直攻
B35: 罚杆 | D35: 杆
B36: 第六杆
B37: 距离： | D37: yd
B38: 方向：
B39: 球位
B40: 是否直攻
B41: 罚杆 | D41: 杆
B42: 第七杆
...

Sheet 13号洞
B2: 标准杆 | C2: 4 | D2: 杆
B3: 成绩 | C3: 5 | D3: 杆
B5: 挥杆&切杆 | E5: 推杆
B6: 第一杆 | C6: 1号木 | E6: 第一推
B7: 距离： | C7: 360 | D7: yd | E7: 距离： | F7: 15 | G7: ft
B8: 方向： | C8: 直球 | E8: 第二推
B9: 球位 | C9: 球道 | E9: 距离： | F9: 2 | G9: ft
B10: 是否直攻 | C10: 过渡 | E10: 第三推
B11: 罚杆 | C11: 0 | D11: 杆 | E11: 距离： | G11: ft
B12: 第二杆 | C12: 7铁 | E12: 第四推
B13: 距离： | C13: 153 | D13: yd | E13: 距离： | G13: ft
B14: 方向： | C14: 直球 | E14: 第五推
B15: 球位 | C15: 球道 | E15: 距离： | G15: ft
B16: 是否直攻 | C16: 直攻 | E16: 第六推
B17: 罚杆 | C17: 0 | D17: 杆 | E17: 距离： | G17: ft
B18: 第三杆 | C18: 56度 | E18: 第七推
B19: 距离： | C19: 20 | D19: yd | E19: 距离： | G19: ft
B20: 方向： | C20: 直球 | E20: 第8推
B21: 球位 | C21: 球道 | E21: 距离： | G21: ft
B22: 是否直攻 | C22: 直攻
B23: 罚杆 | C23: 0 | D23: 杆 | E23: 额外罚杆 | G23: 杆
B24: 第四杆
B25: 距离： | D25: yd
B26: 方向：
B27: 球位
B28: 是否直攻
B29: 罚杆 | D29: 杆
B30: 第五杆
B31: 距离： | D31: yd
B32: 方向：
B33: 球位
B34: 是否直攻
B35: 罚杆 | D35: 杆
B36: 第六杆
B37: 距离： | D37: yd
B38: 方向：
B39: 球位
B40: 是否直攻
B41: 罚杆 | D41: 杆
B42: 第七杆
...

Sheet 14号洞
B2: 标准杆 | C2: 3 | D2: 杆
B3: 成绩 | C3: 3 | D3: 杆
B5: 挥杆&切杆 | E5: 推杆
B6: 第一杆 | C6: 7铁 | E6: 第一推
B7: 距离： | C7: 154 | D7: yd | E7: 距离： | F7: 30 | G7: ft
B8: 方向： | C8: 偏右 | E8: 第二推
B9: 球位 | C9: 球道 | E9: 距离： | F9: 6 | G9: ft
B10: 是否直攻 | C10: 直攻 | E10: 第三推
B11: 罚杆 | C11: 0 | D11: 杆 | E11: 距离： | G11: ft
B12: 第二杆 | E12: 第四推
B13: 距离： | D13: yd | E13: 距离： | G13: ft
B14: 方向： | E14: 第五推
B15: 球位 | E15: 距离： | G15: ft
B16: 是否直攻 | E16: 第六推
B17: 罚杆 | D17: 杆 | E17: 距离： | G17: ft
B18: 第三杆 | E18: 第七推
B19: 距离： | D19: yd | E19: 距离： | G19: ft
B20: 方向： | E20: 第8推
B21: 球位 | E21: 距离： | G21: ft
B22: 是否直攻
B23: 罚杆 | D23: 杆 | E23: 额外罚杆 | G23: 杆
B24: 第四杆
B25: 距离： | D25: yd
B26: 方向：
B27: 球位
B28: 是否直攻
B29: 罚杆 | D29: 杆
B30: 第五杆
B31: 距离： | D31: yd
B32: 方向：
B33: 球位
B34: 是否直攻
B35: 罚杆 | D35: 杆
B36: 第六杆
B37: 距离： | D37: yd
B38: 方向：
B39: 球位
B40: 是否直攻
B41: 罚杆 | D41: 杆
B42: 第七杆
...

Sheet 15号洞
B2: 标准杆 | C2: 4 | D2: 杆
B3: 成绩 | C3: 5 | D3: 杆
B5: 挥杆&切杆 | E5: 推杆
B6: 第一杆 | C6: 1号木 | E6: 第一推
B7: 距离： | C7: 380 | D7: yd | E7: 距离： | F7: 15 | G7: ft
B8: 方向： | C8: 直球 | E8: 第二推
B9: 球位 | C9: 球道 | E9: 距离： | F9: 3 | G9: ft
B10: 是否直攻 | C10: 过渡 | E10: 第三推
B11: 罚杆 | C11: 0 | D11: 杆 | E11: 距离： | G11: ft
B12: 第二杆 | C12: 7铁 | E12: 第四推
B13: 距离： | C13: 190 | D13: yd | E13: 距离： | G13: ft
B14: 方向： | C14: 直球 | E14: 第五推
B15: 球位 | C15: 球道 | E15: 距离： | G15: ft
B16: 是否直攻 | C16: 过渡 | E16: 第六推
B17: 罚杆 | C17: 0 | D17: 杆 | E17: 距离： | G17: ft
B18: 第三杆 | C18: 56度 | E18: 第七推
B19: 距离： | C19: 65 | D19: yd | E19: 距离： | G19: ft
B20: 方向： | C20: 直球 | E20: 第8推
B21: 球位 | C21: 球道 | E21: 距离： | G21: ft
B22: 是否直攻 | C22: 直攻
B23: 罚杆 | C23: 0 | D23: 杆 | E23: 额外罚杆 | G23: 杆
B24: 第四杆
B25: 距离： | D25: yd
B26: 方向：
B27: 球位
B28: 是否直攻
B29: 罚杆 | D29: 杆
B30: 第五杆
B31: 距离： | D31: yd
B32: 方向：
B33: 球位
B34: 是否直攻
B35: 罚杆 | D35: 杆
B36: 第六杆
B37: 距离： | D37: yd
B38: 方向：
B39: 球位
B40: 是否直攻
B41: 罚杆 | D41: 杆
B42: 第七杆
...

Sheet 16号洞
B2: 标准杆 | C2: 3 | D2: 杆
B3: 成绩 | C3: 3 | D3: 杆
B5: 挥杆&切杆 | E5: 推杆
B6: 第一杆 | C6: 7铁 | E6: 第一推
B7: 距离： | C7: 127 | D7: yd | E7: 距离： | F7: 12 | G7: ft
B8: 方向： | C8: 直球 | E8: 第二推
B9: 球位 | C9: 球道 | E9: 距离： | F9: 1 | G9: ft
B10: 是否直攻 | C10: 直攻 | E10: 第三推
B11: 罚杆 | C11: 0 | D11: 杆 | E11: 距离： | G11: ft
B12: 第二杆 | E12: 第四推
B13: 距离： | D13: yd | E13: 距离： | G13: ft
B14: 方向： | E14: 第五推
B15: 球位 | E15: 距离： | G15: ft
B16: 是否直攻 | E16: 第六推
B17: 罚杆 | D17: 杆 | E17: 距离： | G17: ft
B18: 第三杆 | E18: 第七推
B19: 距离： | D19: yd | E19: 距离： | G19: ft
B20: 方向： | E20: 第8推
B21: 球位 | E21: 距离： | G21: ft
B22: 是否直攻
B23: 罚杆 | D23: 杆 | E23: 额外罚杆 | G23: 杆
B24: 第四杆
B25: 距离： | D25: yd
B26: 方向：
B27: 球位
B28: 是否直攻
B29: 罚杆 | D29: 杆
B30: 第五杆
B31: 距离： | D31: yd
B32: 方向：
B33: 球位
B34: 是否直攻
B35: 罚杆 | D35: 杆
B36: 第六杆
B37: 距离： | D37: yd
B38: 方向：
B39: 球位
B40: 是否直攻
B41: 罚杆 | D41: 杆
B42: 第七杆
...

Sheet 17号洞
B2: 标准杆 | C2: 4 | D2: 杆
B3: 成绩 | C3: 5 | D3: 杆
B5: 挥杆&切杆 | E5: 推杆
B6: 第一杆 | C6: 1号木 | E6: 第一推
B7: 距离： | C7: 370 | D7: yd | E7: 距离： | F7: 15 | G7: ft
B8: 方向： | C8: 直球 | E8: 第二推
B9: 球位 | C9: 球道 | E9: 距离： | F9: 1 | G9: ft
B10: 是否直攻 | C10: 过渡 | E10: 第三推
B11: 罚杆 | C11: 0 | D11: 杆 | E11: 距离： | G11: ft
B12: 第二杆 | C12: 球道木 | E12: 第四推
B13: 距离： | C13: 183 | D13: yd | E13: 距离： | G13: ft
B14: 方向： | C14: 直球 | E14: 第五推
B15: 球位 | C15: 球道 | E15: 距离： | G15: ft
B16: 是否直攻 | C16: 直攻 | E16: 第六推
B17: 罚杆 | C17: 0 | D17: 杆 | E17: 距离： | G17: ft
B18: 第三杆 | C18: 56度 | E18: 第七推
B19: 距离： | C19: 11 | D19: yd | E19: 距离： | G19: ft
B20: 方向： | C20: 直球 | E20: 第8推
B21: 球位 | C21: 球道 | E21: 距离： | G21: ft
B22: 是否直攻 | C22: 直攻
B23: 罚杆 | C23: 0 | D23: 杆 | E23: 额外罚杆 | G23: 杆
B24: 第四杆
B25: 距离： | D25: yd
B26: 方向：
B27: 球位
B28: 是否直攻
B29: 罚杆 | D29: 杆
B30: 第五杆
B31: 距离： | D31: yd
B32: 方向：
B33: 球位
B34: 是否直攻
B35: 罚杆 | D35: 杆
B36: 第六杆
B37: 距离： | D37: yd
B38: 方向：
B39: 球位
B40: 是否直攻
B41: 罚杆 | D41: 杆
B42: 第七杆
...

Sheet 18号洞
B2: 标准杆 | C2: 5 | D2: 杆
B3: 成绩 | C3: 6 | D3: 杆
B5: 挥杆&切杆 | E5: 推杆
B6: 第一杆 | C6: 1号木 | E6: 第一推
B7: 距离： | C7: 550 | D7: yd | E7: 距离： | F7: 18 | G7: ft
B8: 方向： | C8: 直球 | E8: 第二推
B9: 球位 | C9: 球道 | E9: 距离： | F9: 4 | G9: ft
B10: 是否直攻 | C10: 过渡 | E10: 第三推
B11: 罚杆 | C11: 0 | D11: 杆 | E11: 距离： | G11: ft
B12: 第二杆 | C12: 球道木 | E12: 第四推
B13: 距离： | C13: 360 | D13: yd | E13: 距离： | G13: ft
B14: 方向： | C14: 直球 | E14: 第五推
B15: 球位 | C15: 球道 | E15: 距离： | G15: ft
B16: 是否直攻 | C16: 过渡 | E16: 第六推
B17: 罚杆 | C17: 0 | D17: 杆 | E17: 距离： | G17: ft
B18: 第三杆 | C18: 球道木 | E18: 第七推
B19: 距离： | C19: 200 | D19: yd | E19: 距离： | G19: ft
B20: 方向： | C20: 直球 | E20: 第8推
B21: 球位 | C21: 球道 | E21: 距离： | G21: ft
B22: 是否直攻 | C22: 过渡
B23: 罚杆 | C23: 0 | D23: 杆 | E23: 额外罚杆 | G23: 杆
B24: 第四杆 | C24: P杆
B25: 距离： | C25: 72 | D25: yd
B26: 方向： | C26: 直球
B27: 球位 | C27: 球道
B28: 是否直攻 | C28: 直攻
B29: 罚杆 | C29: 0 | D29: 杆
B30: 第五杆
B31: 距离： | D31: yd
B32: 方向：
B33: 球位
B34: 是否直攻
B35: 罚杆 | D35: 杆
B36: 第六杆
B37: 距离： | D37: yd
B38: 方向：
B39: 球位
B40: 是否直攻
B41: 罚杆 | D41: 杆
B42: 第七杆
...

Sheet Sheet1
B6: 一推 | C6: 0-3
C7: 3-9
C8: 9-15
C9: 15-30
C10: 30以上
A11: 都是直攻 | B11: 三推 | C11: 9-15
C12: 15-30
C13: 30以上
B14: 救球 | C14: 1有切杆
C15: 2par
C16: 3不标on
C17: 最后切杆距离
B18: 上果岭 | C18: 50-75
C19: 75-100
C20: 100-125
C21: 125-150
C22: 150-200
C23: 200以上
